[E 200329 20:14:16 state:112] [WinError 10061] 由于目标计算机积极拒绝，无法连接。
Traceback (most recent call last):
  File "D:\dcs\communication\protocol\pms.py", line 213, in _cmd
    expected_length=expected_length
  File "C:\Users\zhou\AppData\Local\Programs\Python\Python37\lib\site-packages\modbus_tk\utils.py", line 39, in new
    raise excpt
  File "C:\Users\zhou\AppData\Local\Programs\Python\Python37\lib\site-packages\modbus_tk\utils.py", line 37, in new
    ret = fcn(*args, **kwargs)
  File "C:\Users\zhou\AppData\Local\Programs\Python\Python37\lib\site-packages\modbus_tk\modbus.py", line 152, in execute
    self.open()
  File "C:\Users\zhou\AppData\Local\Programs\Python\Python37\lib\site-packages\modbus_tk\modbus.py", line 99, in open
    self._do_open()
  File "C:\Users\zhou\AppData\Local\Programs\Python\Python37\lib\site-packages\modbus_tk\modbus_tcp.py", line 173, in _do_open
    self._sock.connect((self._host, self._port))
ConnectionRefusedError: [WinError 10061] 由于目标计算机积极拒绝，无法连接。

During handling of the above exception, another exception occurred:

Traceback (most recent call last):
  File "D:\dcs\communication\worker\state.py", line 106, in read
    val = si.read(var)
  File "D:\dcs\communication\worker\state.py", line 159, in read
    return self.dev.read(var)
  File "D:\dcs\communication\protocol\pms.py", line 137, in read
    data = self._cmd(f_code=f_code, address=address, quantity_of_x=length)
  File "D:\dcs\communication\protocol\pms.py", line 216, in _cmd
    raise exception.SkError(exception.NETWORK_ERROR, e)
communication.exception.SkError: [WinError 10061] 由于目标计算机积极拒绝，无法连接。
[E 200329 20:14:42 state:112] [WinError 10061] 由于目标计算机积极拒绝，无法连接。
Traceback (most recent call last):
  File "D:\dcs\communication\protocol\pms.py", line 213, in _cmd
    expected_length=expected_length
  File "C:\Users\zhou\AppData\Local\Programs\Python\Python37\lib\site-packages\modbus_tk\utils.py", line 39, in new
    raise excpt
  File "C:\Users\zhou\AppData\Local\Programs\Python\Python37\lib\site-packages\modbus_tk\utils.py", line 37, in new
    ret = fcn(*args, **kwargs)
  File "C:\Users\zhou\AppData\Local\Programs\Python\Python37\lib\site-packages\modbus_tk\modbus.py", line 152, in execute
    self.open()
  File "C:\Users\zhou\AppData\Local\Programs\Python\Python37\lib\site-packages\modbus_tk\modbus.py", line 99, in open
    self._do_open()
  File "C:\Users\zhou\AppData\Local\Programs\Python\Python37\lib\site-packages\modbus_tk\modbus_tcp.py", line 173, in _do_open
    self._sock.connect((self._host, self._port))
ConnectionRefusedError: [WinError 10061] 由于目标计算机积极拒绝，无法连接。

During handling of the above exception, another exception occurred:

Traceback (most recent call last):
  File "D:\dcs\communication\worker\state.py", line 106, in read
    val = si.read(var)
  File "D:\dcs\communication\worker\state.py", line 159, in read
    return self.dev.read(var)
  File "D:\dcs\communication\protocol\pms.py", line 137, in read
    data = self._cmd(f_code=f_code, address=address, quantity_of_x=length)
  File "D:\dcs\communication\protocol\pms.py", line 216, in _cmd
    raise exception.SkError(exception.NETWORK_ERROR, e)
communication.exception.SkError: [WinError 10061] 由于目标计算机积极拒绝，无法连接。
[E 200329 20:14:44 state:112] [WinError 10061] 由于目标计算机积极拒绝，无法连接。
Traceback (most recent call last):
  File "D:\dcs\communication\protocol\pms.py", line 213, in _cmd
    expected_length=expected_length
  File "C:\Users\zhou\AppData\Local\Programs\Python\Python37\lib\site-packages\modbus_tk\utils.py", line 39, in new
    raise excpt
  File "C:\Users\zhou\AppData\Local\Programs\Python\Python37\lib\site-packages\modbus_tk\utils.py", line 37, in new
    ret = fcn(*args, **kwargs)
  File "C:\Users\zhou\AppData\Local\Programs\Python\Python37\lib\site-packages\modbus_tk\modbus.py", line 152, in execute
    self.open()
  File "C:\Users\zhou\AppData\Local\Programs\Python\Python37\lib\site-packages\modbus_tk\modbus.py", line 99, in open
    self._do_open()
  File "C:\Users\zhou\AppData\Local\Programs\Python\Python37\lib\site-packages\modbus_tk\modbus_tcp.py", line 173, in _do_open
    self._sock.connect((self._host, self._port))
ConnectionRefusedError: [WinError 10061] 由于目标计算机积极拒绝，无法连接。

During handling of the above exception, another exception occurred:

Traceback (most recent call last):
  File "D:\dcs\communication\worker\state.py", line 106, in read
    val = si.read(var)
  File "D:\dcs\communication\worker\state.py", line 159, in read
    return self.dev.read(var)
  File "D:\dcs\communication\protocol\pms.py", line 137, in read
    data = self._cmd(f_code=f_code, address=address, quantity_of_x=length)
  File "D:\dcs\communication\protocol\pms.py", line 216, in _cmd
    raise exception.SkError(exception.NETWORK_ERROR, e)
communication.exception.SkError: [WinError 10061] 由于目标计算机积极拒绝，无法连接。
[E 200329 20:14:46 state:112] [WinError 10061] 由于目标计算机积极拒绝，无法连接。
Traceback (most recent call last):
  File "D:\dcs\communication\protocol\pms.py", line 213, in _cmd
    expected_length=expected_length
  File "C:\Users\zhou\AppData\Local\Programs\Python\Python37\lib\site-packages\modbus_tk\utils.py", line 39, in new
    raise excpt
  File "C:\Users\zhou\AppData\Local\Programs\Python\Python37\lib\site-packages\modbus_tk\utils.py", line 37, in new
    ret = fcn(*args, **kwargs)
  File "C:\Users\zhou\AppData\Local\Programs\Python\Python37\lib\site-packages\modbus_tk\modbus.py", line 152, in execute
    self.open()
  File "C:\Users\zhou\AppData\Local\Programs\Python\Python37\lib\site-packages\modbus_tk\modbus.py", line 99, in open
    self._do_open()
  File "C:\Users\zhou\AppData\Local\Programs\Python\Python37\lib\site-packages\modbus_tk\modbus_tcp.py", line 173, in _do_open
    self._sock.connect((self._host, self._port))
ConnectionRefusedError: [WinError 10061] 由于目标计算机积极拒绝，无法连接。

During handling of the above exception, another exception occurred:

Traceback (most recent call last):
  File "D:\dcs\communication\worker\state.py", line 106, in read
    val = si.read(var)
  File "D:\dcs\communication\worker\state.py", line 159, in read
    return self.dev.read(var)
  File "D:\dcs\communication\protocol\pms.py", line 137, in read
    data = self._cmd(f_code=f_code, address=address, quantity_of_x=length)
  File "D:\dcs\communication\protocol\pms.py", line 216, in _cmd
    raise exception.SkError(exception.NETWORK_ERROR, e)
communication.exception.SkError: [WinError 10061] 由于目标计算机积极拒绝，无法连接。
[E 200329 20:29:33 state:107] [WinError 10061] 由于目标计算机积极拒绝，无法连接。
Traceback (most recent call last):
  File "D:\dcs\RealtimeDB\protocol\pms.py", line 213, in _cmd
    expected_length=expected_length
  File "C:\Users\zhou\AppData\Local\Programs\Python\Python37\lib\site-packages\modbus_tk\utils.py", line 39, in new
    raise excpt
  File "C:\Users\zhou\AppData\Local\Programs\Python\Python37\lib\site-packages\modbus_tk\utils.py", line 37, in new
    ret = fcn(*args, **kwargs)
  File "C:\Users\zhou\AppData\Local\Programs\Python\Python37\lib\site-packages\modbus_tk\modbus.py", line 152, in execute
    self.open()
  File "C:\Users\zhou\AppData\Local\Programs\Python\Python37\lib\site-packages\modbus_tk\modbus.py", line 99, in open
    self._do_open()
  File "C:\Users\zhou\AppData\Local\Programs\Python\Python37\lib\site-packages\modbus_tk\modbus_tcp.py", line 173, in _do_open
    self._sock.connect((self._host, self._port))
ConnectionRefusedError: [WinError 10061] 由于目标计算机积极拒绝，无法连接。

During handling of the above exception, another exception occurred:

Traceback (most recent call last):
  File "D:\dcs\RealtimeDB\worker\state.py", line 103, in read
    val = si.read(var)
  File "D:\dcs\RealtimeDB\worker\state.py", line 152, in read
    return self.dev.read(var)
  File "D:\dcs\RealtimeDB\protocol\pms.py", line 137, in read
    data = self._cmd(f_code=f_code, address=address, quantity_of_x=length)
  File "D:\dcs\RealtimeDB\protocol\pms.py", line 216, in _cmd
    raise exception.SkError(exception.NETWORK_ERROR, e)
RealtimeDB.exception.SkError: [WinError 10061] 由于目标计算机积极拒绝，无法连接。
[I 200330 14:02:53 state:121] write kwargs=RCS-JE-FT101A, 1.0, True, {}; IVar(id=46, name='RCS-JE-FT101A', sig_type=<SigType.SAO: 12>, chr=<ValType.D64: 10>, reg=31084, length=1, uri='', slot='PXI1SLOT8', si=None, engineering_unit='amps', rlo=4.0, rhi=20.0, elo=0.004, ehi=0.02)
[E 200330 14:02:55 state:131] [WinError 10061] 由于目标计算机积极拒绝，无法连接。
Traceback (most recent call last):
  File "D:\dcs\RealtimeDB\protocol\pms.py", line 213, in _cmd
    expected_length=expected_length
  File "C:\Users\zhou\AppData\Local\Programs\Python\Python37\lib\site-packages\modbus_tk\utils.py", line 39, in new
    raise excpt
  File "C:\Users\zhou\AppData\Local\Programs\Python\Python37\lib\site-packages\modbus_tk\utils.py", line 37, in new
    ret = fcn(*args, **kwargs)
  File "C:\Users\zhou\AppData\Local\Programs\Python\Python37\lib\site-packages\modbus_tk\modbus.py", line 152, in execute
    self.open()
  File "C:\Users\zhou\AppData\Local\Programs\Python\Python37\lib\site-packages\modbus_tk\modbus.py", line 99, in open
    self._do_open()
  File "C:\Users\zhou\AppData\Local\Programs\Python\Python37\lib\site-packages\modbus_tk\modbus_tcp.py", line 173, in _do_open
    self._sock.connect((self._host, self._port))
ConnectionRefusedError: [WinError 10061] 由于目标计算机积极拒绝，无法连接。

During handling of the above exception, another exception occurred:

Traceback (most recent call last):
  File "D:\dcs\RealtimeDB\worker\state.py", line 127, in write
    value = si.write(var, value)
  File "D:\dcs\RealtimeDB\worker\state.py", line 155, in write
    return self.dev.write(var, value)
  File "D:\dcs\RealtimeDB\protocol\pms.py", line 194, in write
    self._cmd(f_code=cst.WRITE_MULTIPLE_REGISTERS, address=address, output_value=output_value)
  File "D:\dcs\RealtimeDB\protocol\pms.py", line 216, in _cmd
    raise exception.SkError(exception.NETWORK_ERROR, e)
RealtimeDB.exception.SkError: [WinError 10061] 由于目标计算机积极拒绝，无法连接。
[I 200604 11:05:29 state:121] write kwargs=, 1.0, True, {}; IVar(id=34, name='', sig_type=<SigType.SAO: 12>, chr=<ValType.D64: 10>, reg=31036, length=1, uri='', slot='PXI1SLOT8', si=None, engineering_unit='', rlo=None, rhi=None, elo=None, ehi=None)
[E 200604 11:05:31 state:131] [WinError 10061] 由于目标计算机积极拒绝，无法连接。
Traceback (most recent call last):
  File "E:\dcstms-master-20f6bed99520780ab38cba522db07524a5d40c1c\RealtimeDB\protocol\pms.py", line 213, in _cmd
    expected_length=expected_length
  File "C:\Users\zhous\AppData\Local\Programs\Python\Python37-32\lib\site-packages\modbus_tk\utils.py", line 39, in new
    raise excpt
  File "C:\Users\zhous\AppData\Local\Programs\Python\Python37-32\lib\site-packages\modbus_tk\utils.py", line 37, in new
    ret = fcn(*args, **kwargs)
  File "C:\Users\zhous\AppData\Local\Programs\Python\Python37-32\lib\site-packages\modbus_tk\modbus.py", line 152, in execute
    self.open()
  File "C:\Users\zhous\AppData\Local\Programs\Python\Python37-32\lib\site-packages\modbus_tk\modbus.py", line 99, in open
    self._do_open()
  File "C:\Users\zhous\AppData\Local\Programs\Python\Python37-32\lib\site-packages\modbus_tk\modbus_tcp.py", line 173, in _do_open
    self._sock.connect((self._host, self._port))
ConnectionRefusedError: [WinError 10061] 由于目标计算机积极拒绝，无法连接。

During handling of the above exception, another exception occurred:

Traceback (most recent call last):
  File "E:\dcstms-master-20f6bed99520780ab38cba522db07524a5d40c1c\RealtimeDB\worker\state.py", line 127, in write
    value = si.write(var, value)
  File "E:\dcstms-master-20f6bed99520780ab38cba522db07524a5d40c1c\RealtimeDB\worker\state.py", line 155, in write
    return self.dev.write(var, value)
  File "E:\dcstms-master-20f6bed99520780ab38cba522db07524a5d40c1c\RealtimeDB\protocol\pms.py", line 194, in write
    self._cmd(f_code=cst.WRITE_MULTIPLE_REGISTERS, address=address, output_value=output_value)
  File "E:\dcstms-master-20f6bed99520780ab38cba522db07524a5d40c1c\RealtimeDB\protocol\pms.py", line 216, in _cmd
    raise exception.SkError(exception.NETWORK_ERROR, e)
RealtimeDB.exception.SkError: [WinError 10061] 由于目标计算机积极拒绝，无法连接。
[E 200604 11:12:11 state:112] [WinError 10061] 由于目标计算机积极拒绝，无法连接。
Traceback (most recent call last):
  File "E:\dcstms-master-20f6bed99520780ab38cba522db07524a5d40c1c\communication\protocol\pms.py", line 213, in _cmd
    expected_length=expected_length
  File "C:\Users\zhous\AppData\Local\Programs\Python\Python37-32\lib\site-packages\modbus_tk\utils.py", line 39, in new
    raise excpt
  File "C:\Users\zhous\AppData\Local\Programs\Python\Python37-32\lib\site-packages\modbus_tk\utils.py", line 37, in new
    ret = fcn(*args, **kwargs)
  File "C:\Users\zhous\AppData\Local\Programs\Python\Python37-32\lib\site-packages\modbus_tk\modbus.py", line 152, in execute
    self.open()
  File "C:\Users\zhous\AppData\Local\Programs\Python\Python37-32\lib\site-packages\modbus_tk\modbus.py", line 99, in open
    self._do_open()
  File "C:\Users\zhous\AppData\Local\Programs\Python\Python37-32\lib\site-packages\modbus_tk\modbus_tcp.py", line 173, in _do_open
    self._sock.connect((self._host, self._port))
ConnectionRefusedError: [WinError 10061] 由于目标计算机积极拒绝，无法连接。

During handling of the above exception, another exception occurred:

Traceback (most recent call last):
  File "E:\dcstms-master-20f6bed99520780ab38cba522db07524a5d40c1c\communication\worker\state.py", line 106, in read
    val = si.read(var)
  File "E:\dcstms-master-20f6bed99520780ab38cba522db07524a5d40c1c\communication\worker\state.py", line 159, in read
    return self.dev.read(var)
  File "E:\dcstms-master-20f6bed99520780ab38cba522db07524a5d40c1c\communication\protocol\pms.py", line 137, in read
    data = self._cmd(f_code=f_code, address=address, quantity_of_x=length)
  File "E:\dcstms-master-20f6bed99520780ab38cba522db07524a5d40c1c\communication\protocol\pms.py", line 216, in _cmd
    raise exception.SkError(exception.NETWORK_ERROR, e)
communication.exception.SkError: [WinError 10061] 由于目标计算机积极拒绝，无法连接。
[E 200604 11:12:13 state:112] [WinError 10061] 由于目标计算机积极拒绝，无法连接。
Traceback (most recent call last):
  File "E:\dcstms-master-20f6bed99520780ab38cba522db07524a5d40c1c\communication\protocol\pms.py", line 213, in _cmd
    expected_length=expected_length
  File "C:\Users\zhous\AppData\Local\Programs\Python\Python37-32\lib\site-packages\modbus_tk\utils.py", line 39, in new
    raise excpt
  File "C:\Users\zhous\AppData\Local\Programs\Python\Python37-32\lib\site-packages\modbus_tk\utils.py", line 37, in new
    ret = fcn(*args, **kwargs)
  File "C:\Users\zhous\AppData\Local\Programs\Python\Python37-32\lib\site-packages\modbus_tk\modbus.py", line 152, in execute
    self.open()
  File "C:\Users\zhous\AppData\Local\Programs\Python\Python37-32\lib\site-packages\modbus_tk\modbus.py", line 99, in open
    self._do_open()
  File "C:\Users\zhous\AppData\Local\Programs\Python\Python37-32\lib\site-packages\modbus_tk\modbus_tcp.py", line 173, in _do_open
    self._sock.connect((self._host, self._port))
ConnectionRefusedError: [WinError 10061] 由于目标计算机积极拒绝，无法连接。

During handling of the above exception, another exception occurred:

Traceback (most recent call last):
  File "E:\dcstms-master-20f6bed99520780ab38cba522db07524a5d40c1c\communication\worker\state.py", line 106, in read
    val = si.read(var)
  File "E:\dcstms-master-20f6bed99520780ab38cba522db07524a5d40c1c\communication\worker\state.py", line 159, in read
    return self.dev.read(var)
  File "E:\dcstms-master-20f6bed99520780ab38cba522db07524a5d40c1c\communication\protocol\pms.py", line 137, in read
    data = self._cmd(f_code=f_code, address=address, quantity_of_x=length)
  File "E:\dcstms-master-20f6bed99520780ab38cba522db07524a5d40c1c\communication\protocol\pms.py", line 216, in _cmd
    raise exception.SkError(exception.NETWORK_ERROR, e)
communication.exception.SkError: [WinError 10061] 由于目标计算机积极拒绝，无法连接。
[E 200604 11:12:38 state:112] [WinError 10061] 由于目标计算机积极拒绝，无法连接。
Traceback (most recent call last):
  File "E:\dcstms-master-20f6bed99520780ab38cba522db07524a5d40c1c\communication\protocol\pms.py", line 213, in _cmd
    expected_length=expected_length
  File "C:\Users\zhous\AppData\Local\Programs\Python\Python37-32\lib\site-packages\modbus_tk\utils.py", line 39, in new
    raise excpt
  File "C:\Users\zhous\AppData\Local\Programs\Python\Python37-32\lib\site-packages\modbus_tk\utils.py", line 37, in new
    ret = fcn(*args, **kwargs)
  File "C:\Users\zhous\AppData\Local\Programs\Python\Python37-32\lib\site-packages\modbus_tk\modbus.py", line 152, in execute
    self.open()
  File "C:\Users\zhous\AppData\Local\Programs\Python\Python37-32\lib\site-packages\modbus_tk\modbus.py", line 99, in open
    self._do_open()
  File "C:\Users\zhous\AppData\Local\Programs\Python\Python37-32\lib\site-packages\modbus_tk\modbus_tcp.py", line 173, in _do_open
    self._sock.connect((self._host, self._port))
ConnectionRefusedError: [WinError 10061] 由于目标计算机积极拒绝，无法连接。

During handling of the above exception, another exception occurred:

Traceback (most recent call last):
  File "E:\dcstms-master-20f6bed99520780ab38cba522db07524a5d40c1c\communication\worker\state.py", line 106, in read
    val = si.read(var)
  File "E:\dcstms-master-20f6bed99520780ab38cba522db07524a5d40c1c\communication\worker\state.py", line 159, in read
    return self.dev.read(var)
  File "E:\dcstms-master-20f6bed99520780ab38cba522db07524a5d40c1c\communication\protocol\pms.py", line 137, in read
    data = self._cmd(f_code=f_code, address=address, quantity_of_x=length)
  File "E:\dcstms-master-20f6bed99520780ab38cba522db07524a5d40c1c\communication\protocol\pms.py", line 216, in _cmd
    raise exception.SkError(exception.NETWORK_ERROR, e)
communication.exception.SkError: [WinError 10061] 由于目标计算机积极拒绝，无法连接。
[E 200604 11:12:40 state:112] [WinError 10061] 由于目标计算机积极拒绝，无法连接。
Traceback (most recent call last):
  File "E:\dcstms-master-20f6bed99520780ab38cba522db07524a5d40c1c\communication\protocol\pms.py", line 213, in _cmd
    expected_length=expected_length
  File "C:\Users\zhous\AppData\Local\Programs\Python\Python37-32\lib\site-packages\modbus_tk\utils.py", line 39, in new
    raise excpt
  File "C:\Users\zhous\AppData\Local\Programs\Python\Python37-32\lib\site-packages\modbus_tk\utils.py", line 37, in new
    ret = fcn(*args, **kwargs)
  File "C:\Users\zhous\AppData\Local\Programs\Python\Python37-32\lib\site-packages\modbus_tk\modbus.py", line 152, in execute
    self.open()
  File "C:\Users\zhous\AppData\Local\Programs\Python\Python37-32\lib\site-packages\modbus_tk\modbus.py", line 99, in open
    self._do_open()
  File "C:\Users\zhous\AppData\Local\Programs\Python\Python37-32\lib\site-packages\modbus_tk\modbus_tcp.py", line 173, in _do_open
    self._sock.connect((self._host, self._port))
ConnectionRefusedError: [WinError 10061] 由于目标计算机积极拒绝，无法连接。

During handling of the above exception, another exception occurred:

Traceback (most recent call last):
  File "E:\dcstms-master-20f6bed99520780ab38cba522db07524a5d40c1c\communication\worker\state.py", line 106, in read
    val = si.read(var)
  File "E:\dcstms-master-20f6bed99520780ab38cba522db07524a5d40c1c\communication\worker\state.py", line 159, in read
    return self.dev.read(var)
  File "E:\dcstms-master-20f6bed99520780ab38cba522db07524a5d40c1c\communication\protocol\pms.py", line 137, in read
    data = self._cmd(f_code=f_code, address=address, quantity_of_x=length)
  File "E:\dcstms-master-20f6bed99520780ab38cba522db07524a5d40c1c\communication\protocol\pms.py", line 216, in _cmd
    raise exception.SkError(exception.NETWORK_ERROR, e)
communication.exception.SkError: [WinError 10061] 由于目标计算机积极拒绝，无法连接。
[E 200604 11:34:55 state:107] [WinError 10061] 由于目标计算机积极拒绝，无法连接。
Traceback (most recent call last):
  File "E:\dcstms-master-20f6bed99520780ab38cba522db07524a5d40c1c\RealtimeDB\protocol\pms.py", line 213, in _cmd
    expected_length=expected_length
  File "C:\Users\zhous\AppData\Local\Programs\Python\Python37-32\lib\site-packages\modbus_tk\utils.py", line 39, in new
    raise excpt
  File "C:\Users\zhous\AppData\Local\Programs\Python\Python37-32\lib\site-packages\modbus_tk\utils.py", line 37, in new
    ret = fcn(*args, **kwargs)
  File "C:\Users\zhous\AppData\Local\Programs\Python\Python37-32\lib\site-packages\modbus_tk\modbus.py", line 152, in execute
    self.open()
  File "C:\Users\zhous\AppData\Local\Programs\Python\Python37-32\lib\site-packages\modbus_tk\modbus.py", line 99, in open
    self._do_open()
  File "C:\Users\zhous\AppData\Local\Programs\Python\Python37-32\lib\site-packages\modbus_tk\modbus_tcp.py", line 173, in _do_open
    self._sock.connect((self._host, self._port))
ConnectionRefusedError: [WinError 10061] 由于目标计算机积极拒绝，无法连接。

During handling of the above exception, another exception occurred:

Traceback (most recent call last):
  File "E:\dcstms-master-20f6bed99520780ab38cba522db07524a5d40c1c\RealtimeDB\worker\state.py", line 103, in read
    val = si.read(var)
  File "E:\dcstms-master-20f6bed99520780ab38cba522db07524a5d40c1c\RealtimeDB\worker\state.py", line 152, in read
    return self.dev.read(var)
  File "E:\dcstms-master-20f6bed99520780ab38cba522db07524a5d40c1c\RealtimeDB\protocol\pms.py", line 137, in read
    data = self._cmd(f_code=f_code, address=address, quantity_of_x=length)
  File "E:\dcstms-master-20f6bed99520780ab38cba522db07524a5d40c1c\RealtimeDB\protocol\pms.py", line 216, in _cmd
    raise exception.SkError(exception.NETWORK_ERROR, e)
RealtimeDB.exception.SkError: [WinError 10061] 由于目标计算机积极拒绝，无法连接。
[E 200604 11:35:18 state:107] [WinError 10061] 由于目标计算机积极拒绝，无法连接。
Traceback (most recent call last):
  File "E:\dcstms-master-20f6bed99520780ab38cba522db07524a5d40c1c\RealtimeDB\protocol\pms.py", line 213, in _cmd
    expected_length=expected_length
  File "C:\Users\zhous\AppData\Local\Programs\Python\Python37-32\lib\site-packages\modbus_tk\utils.py", line 39, in new
    raise excpt
  File "C:\Users\zhous\AppData\Local\Programs\Python\Python37-32\lib\site-packages\modbus_tk\utils.py", line 37, in new
    ret = fcn(*args, **kwargs)
  File "C:\Users\zhous\AppData\Local\Programs\Python\Python37-32\lib\site-packages\modbus_tk\modbus.py", line 152, in execute
    self.open()
  File "C:\Users\zhous\AppData\Local\Programs\Python\Python37-32\lib\site-packages\modbus_tk\modbus.py", line 99, in open
    self._do_open()
  File "C:\Users\zhous\AppData\Local\Programs\Python\Python37-32\lib\site-packages\modbus_tk\modbus_tcp.py", line 173, in _do_open
    self._sock.connect((self._host, self._port))
ConnectionRefusedError: [WinError 10061] 由于目标计算机积极拒绝，无法连接。

During handling of the above exception, another exception occurred:

Traceback (most recent call last):
  File "E:\dcstms-master-20f6bed99520780ab38cba522db07524a5d40c1c\RealtimeDB\worker\state.py", line 103, in read
    val = si.read(var)
  File "E:\dcstms-master-20f6bed99520780ab38cba522db07524a5d40c1c\RealtimeDB\worker\state.py", line 152, in read
    return self.dev.read(var)
  File "E:\dcstms-master-20f6bed99520780ab38cba522db07524a5d40c1c\RealtimeDB\protocol\pms.py", line 137, in read
    data = self._cmd(f_code=f_code, address=address, quantity_of_x=length)
  File "E:\dcstms-master-20f6bed99520780ab38cba522db07524a5d40c1c\RealtimeDB\protocol\pms.py", line 216, in _cmd
    raise exception.SkError(exception.NETWORK_ERROR, e)
RealtimeDB.exception.SkError: [WinError 10061] 由于目标计算机积极拒绝，无法连接。
[E 200604 14:17:23 state:107] [WinError 10061] 由于目标计算机积极拒绝，无法连接。
Traceback (most recent call last):
  File "E:\dcstms-master-20f6bed99520780ab38cba522db07524a5d40c1c\RealtimeDB\protocol\pms.py", line 213, in _cmd
    expected_length=expected_length
  File "C:\Users\zhous\AppData\Local\Programs\Python\Python37-32\lib\site-packages\modbus_tk\utils.py", line 39, in new
    raise excpt
  File "C:\Users\zhous\AppData\Local\Programs\Python\Python37-32\lib\site-packages\modbus_tk\utils.py", line 37, in new
    ret = fcn(*args, **kwargs)
  File "C:\Users\zhous\AppData\Local\Programs\Python\Python37-32\lib\site-packages\modbus_tk\modbus.py", line 152, in execute
    self.open()
  File "C:\Users\zhous\AppData\Local\Programs\Python\Python37-32\lib\site-packages\modbus_tk\modbus.py", line 99, in open
    self._do_open()
  File "C:\Users\zhous\AppData\Local\Programs\Python\Python37-32\lib\site-packages\modbus_tk\modbus_tcp.py", line 173, in _do_open
    self._sock.connect((self._host, self._port))
ConnectionRefusedError: [WinError 10061] 由于目标计算机积极拒绝，无法连接。

During handling of the above exception, another exception occurred:

Traceback (most recent call last):
  File "E:\dcstms-master-20f6bed99520780ab38cba522db07524a5d40c1c\RealtimeDB\worker\state.py", line 103, in read
    val = si.read(var)
  File "E:\dcstms-master-20f6bed99520780ab38cba522db07524a5d40c1c\RealtimeDB\worker\state.py", line 152, in read
    return self.dev.read(var)
  File "E:\dcstms-master-20f6bed99520780ab38cba522db07524a5d40c1c\RealtimeDB\protocol\pms.py", line 137, in read
    data = self._cmd(f_code=f_code, address=address, quantity_of_x=length)
  File "E:\dcstms-master-20f6bed99520780ab38cba522db07524a5d40c1c\RealtimeDB\protocol\pms.py", line 216, in _cmd
    raise exception.SkError(exception.NETWORK_ERROR, e)
RealtimeDB.exception.SkError: [WinError 10061] 由于目标计算机积极拒绝，无法连接。
[E 200604 14:17:58 state:107] [WinError 10061] 由于目标计算机积极拒绝，无法连接。
Traceback (most recent call last):
  File "E:\dcstms-master-20f6bed99520780ab38cba522db07524a5d40c1c\RealtimeDB\protocol\pms.py", line 213, in _cmd
    expected_length=expected_length
  File "C:\Users\zhous\AppData\Local\Programs\Python\Python37-32\lib\site-packages\modbus_tk\utils.py", line 39, in new
    raise excpt
  File "C:\Users\zhous\AppData\Local\Programs\Python\Python37-32\lib\site-packages\modbus_tk\utils.py", line 37, in new
    ret = fcn(*args, **kwargs)
  File "C:\Users\zhous\AppData\Local\Programs\Python\Python37-32\lib\site-packages\modbus_tk\modbus.py", line 152, in execute
    self.open()
  File "C:\Users\zhous\AppData\Local\Programs\Python\Python37-32\lib\site-packages\modbus_tk\modbus.py", line 99, in open
    self._do_open()
  File "C:\Users\zhous\AppData\Local\Programs\Python\Python37-32\lib\site-packages\modbus_tk\modbus_tcp.py", line 173, in _do_open
    self._sock.connect((self._host, self._port))
ConnectionRefusedError: [WinError 10061] 由于目标计算机积极拒绝，无法连接。

During handling of the above exception, another exception occurred:

Traceback (most recent call last):
  File "E:\dcstms-master-20f6bed99520780ab38cba522db07524a5d40c1c\RealtimeDB\worker\state.py", line 103, in read
    val = si.read(var)
  File "E:\dcstms-master-20f6bed99520780ab38cba522db07524a5d40c1c\RealtimeDB\worker\state.py", line 152, in read
    return self.dev.read(var)
  File "E:\dcstms-master-20f6bed99520780ab38cba522db07524a5d40c1c\RealtimeDB\protocol\pms.py", line 137, in read
    data = self._cmd(f_code=f_code, address=address, quantity_of_x=length)
  File "E:\dcstms-master-20f6bed99520780ab38cba522db07524a5d40c1c\RealtimeDB\protocol\pms.py", line 216, in _cmd
    raise exception.SkError(exception.NETWORK_ERROR, e)
RealtimeDB.exception.SkError: [WinError 10061] 由于目标计算机积极拒绝，无法连接。
[E 200604 14:31:15 state:107] [WinError 10061] 由于目标计算机积极拒绝，无法连接。
Traceback (most recent call last):
  File "E:\dcstms-master-20f6bed99520780ab38cba522db07524a5d40c1c\RealtimeDB\protocol\pms.py", line 213, in _cmd
    expected_length=expected_length
  File "C:\Users\zhous\AppData\Local\Programs\Python\Python37-32\lib\site-packages\modbus_tk\utils.py", line 39, in new
    raise excpt
  File "C:\Users\zhous\AppData\Local\Programs\Python\Python37-32\lib\site-packages\modbus_tk\utils.py", line 37, in new
    ret = fcn(*args, **kwargs)
  File "C:\Users\zhous\AppData\Local\Programs\Python\Python37-32\lib\site-packages\modbus_tk\modbus.py", line 152, in execute
    self.open()
  File "C:\Users\zhous\AppData\Local\Programs\Python\Python37-32\lib\site-packages\modbus_tk\modbus.py", line 99, in open
    self._do_open()
  File "C:\Users\zhous\AppData\Local\Programs\Python\Python37-32\lib\site-packages\modbus_tk\modbus_tcp.py", line 173, in _do_open
    self._sock.connect((self._host, self._port))
ConnectionRefusedError: [WinError 10061] 由于目标计算机积极拒绝，无法连接。

During handling of the above exception, another exception occurred:

Traceback (most recent call last):
  File "E:\dcstms-master-20f6bed99520780ab38cba522db07524a5d40c1c\RealtimeDB\worker\state.py", line 103, in read
    val = si.read(var)
  File "E:\dcstms-master-20f6bed99520780ab38cba522db07524a5d40c1c\RealtimeDB\worker\state.py", line 152, in read
    return self.dev.read(var)
  File "E:\dcstms-master-20f6bed99520780ab38cba522db07524a5d40c1c\RealtimeDB\protocol\pms.py", line 137, in read
    data = self._cmd(f_code=f_code, address=address, quantity_of_x=length)
  File "E:\dcstms-master-20f6bed99520780ab38cba522db07524a5d40c1c\RealtimeDB\protocol\pms.py", line 216, in _cmd
    raise exception.SkError(exception.NETWORK_ERROR, e)
RealtimeDB.exception.SkError: [WinError 10061] 由于目标计算机积极拒绝，无法连接。
[E 200604 14:35:55 state:107] [WinError 10061] 由于目标计算机积极拒绝，无法连接。
Traceback (most recent call last):
  File "E:\dcstms-master-20f6bed99520780ab38cba522db07524a5d40c1c\RealtimeDB\protocol\pms.py", line 213, in _cmd
    expected_length=expected_length
  File "C:\Users\zhous\AppData\Local\Programs\Python\Python37-32\lib\site-packages\modbus_tk\utils.py", line 39, in new
    raise excpt
  File "C:\Users\zhous\AppData\Local\Programs\Python\Python37-32\lib\site-packages\modbus_tk\utils.py", line 37, in new
    ret = fcn(*args, **kwargs)
  File "C:\Users\zhous\AppData\Local\Programs\Python\Python37-32\lib\site-packages\modbus_tk\modbus.py", line 152, in execute
    self.open()
  File "C:\Users\zhous\AppData\Local\Programs\Python\Python37-32\lib\site-packages\modbus_tk\modbus.py", line 99, in open
    self._do_open()
  File "C:\Users\zhous\AppData\Local\Programs\Python\Python37-32\lib\site-packages\modbus_tk\modbus_tcp.py", line 173, in _do_open
    self._sock.connect((self._host, self._port))
ConnectionRefusedError: [WinError 10061] 由于目标计算机积极拒绝，无法连接。

During handling of the above exception, another exception occurred:

Traceback (most recent call last):
  File "E:\dcstms-master-20f6bed99520780ab38cba522db07524a5d40c1c\RealtimeDB\worker\state.py", line 103, in read
    val = si.read(var)
  File "E:\dcstms-master-20f6bed99520780ab38cba522db07524a5d40c1c\RealtimeDB\worker\state.py", line 152, in read
    return self.dev.read(var)
  File "E:\dcstms-master-20f6bed99520780ab38cba522db07524a5d40c1c\RealtimeDB\protocol\pms.py", line 137, in read
    data = self._cmd(f_code=f_code, address=address, quantity_of_x=length)
  File "E:\dcstms-master-20f6bed99520780ab38cba522db07524a5d40c1c\RealtimeDB\protocol\pms.py", line 216, in _cmd
    raise exception.SkError(exception.NETWORK_ERROR, e)
RealtimeDB.exception.SkError: [WinError 10061] 由于目标计算机积极拒绝，无法连接。
[E 200621 22:23:21 state:112] [WinError 10061] 由于目标计算机积极拒绝，无法连接。
Traceback (most recent call last):
  File "C:\Users\zhous\Desktop\新建文件夹 (7)\dcstms-master-20f6bed99520780ab38cba522db07524a5d40c1c\communication\protocol\pms.py", line 213, in _cmd
    expected_length=expected_length
  File "C:\Users\zhous\AppData\Local\Programs\Python\Python37-32\lib\site-packages\modbus_tk\utils.py", line 39, in new
    raise excpt
  File "C:\Users\zhous\AppData\Local\Programs\Python\Python37-32\lib\site-packages\modbus_tk\utils.py", line 37, in new
    ret = fcn(*args, **kwargs)
  File "C:\Users\zhous\AppData\Local\Programs\Python\Python37-32\lib\site-packages\modbus_tk\modbus.py", line 152, in execute
    self.open()
  File "C:\Users\zhous\AppData\Local\Programs\Python\Python37-32\lib\site-packages\modbus_tk\modbus.py", line 99, in open
    self._do_open()
  File "C:\Users\zhous\AppData\Local\Programs\Python\Python37-32\lib\site-packages\modbus_tk\modbus_tcp.py", line 173, in _do_open
    self._sock.connect((self._host, self._port))
ConnectionRefusedError: [WinError 10061] 由于目标计算机积极拒绝，无法连接。

During handling of the above exception, another exception occurred:

Traceback (most recent call last):
  File "C:\Users\zhous\Desktop\新建文件夹 (7)\dcstms-master-20f6bed99520780ab38cba522db07524a5d40c1c\communication\worker\state.py", line 106, in read
    val = si.read(var)
  File "C:\Users\zhous\Desktop\新建文件夹 (7)\dcstms-master-20f6bed99520780ab38cba522db07524a5d40c1c\communication\worker\state.py", line 159, in read
    return self.dev.read(var)
  File "C:\Users\zhous\Desktop\新建文件夹 (7)\dcstms-master-20f6bed99520780ab38cba522db07524a5d40c1c\communication\protocol\pms.py", line 137, in read
    data = self._cmd(f_code=f_code, address=address, quantity_of_x=length)
  File "C:\Users\zhous\Desktop\新建文件夹 (7)\dcstms-master-20f6bed99520780ab38cba522db07524a5d40c1c\communication\protocol\pms.py", line 216, in _cmd
    raise exception.SkError(exception.NETWORK_ERROR, e)
communication.exception.SkError: [WinError 10061] 由于目标计算机积极拒绝，无法连接。
[I 200622 11:30:12 state:121] write kwargs=SFS-JE-LT019A, 1.0, True, {}; IVar(id=51, name='SFS-JE-LT019A', sig_type=<SigType.SAO: 12>, chr=<ValType.D64: 10>, reg=31104, length=1, uri='', slot='PXI1SLOT8', si=None, engineering_unit='amps', rlo=4.0, rhi=20.0, elo=0.004, ehi=0.02)
[I 200622 11:30:16 state:121] write kwargs=RCS-JE-TE121A-E2, 1.0, True, {}; IVar(id=57, name='RCS-JE-TE121A-E2', sig_type=<SigType.SAO: 12>, chr=<ValType.D64: 10>, reg=32000, length=1, uri='', slot='PXI1SLOT9', si=None, engineering_unit='OHMS', rlo=91.579923, rhi=253.133557, elo=0.0, ehi=10.0)
